2021-03-02 11:36:01,232 ERROR: Exception on /index [GET] [in c:\users\sty_l\microblog\venv\lib\site-packages\flask\app.py:1892]
Traceback (most recent call last):
  File "c:\users\sty_l\microblog\venv\lib\site-packages\flask\app.py", line 2447, in wsgi_app
    response = self.full_dispatch_request()
  File "c:\users\sty_l\microblog\venv\lib\site-packages\flask\app.py", line 1952, in full_dispatch_request
    rv = self.handle_user_exception(e)
  File "c:\users\sty_l\microblog\venv\lib\site-packages\flask\app.py", line 1821, in handle_user_exception
    reraise(exc_type, exc_value, tb)
  File "c:\users\sty_l\microblog\venv\lib\site-packages\flask\_compat.py", line 39, in reraise
    raise value
  File "c:\users\sty_l\microblog\venv\lib\site-packages\flask\app.py", line 1950, in full_dispatch_request
    rv = self.dispatch_request()
  File "c:\users\sty_l\microblog\venv\lib\site-packages\flask\app.py", line 1936, in dispatch_request
    return self.view_functions[rule.endpoint](**req.view_args)
  File "c:\users\sty_l\microblog\venv\lib\site-packages\flask_login\utils.py", line 272, in decorated_view
    return func(*args, **kwargs)
  File "C:\Users\sty_l\microblog\app\routes.py", line 33, in index
    posts=posts)
  File "c:\users\sty_l\microblog\venv\lib\site-packages\flask\templating.py", line 138, in render_template
    ctx.app.jinja_env.get_or_select_template(template_name_or_list),
  File "c:\users\sty_l\microblog\venv\lib\site-packages\jinja2\environment.py", line 930, in get_or_select_template
    return self.get_template(template_name_or_list, parent, globals)
  File "c:\users\sty_l\microblog\venv\lib\site-packages\jinja2\environment.py", line 883, in get_template
    return self._load_template(name, self.make_globals(globals))
  File "c:\users\sty_l\microblog\venv\lib\site-packages\jinja2\environment.py", line 857, in _load_template
    template = self.loader.load(self, name, globals)
  File "c:\users\sty_l\microblog\venv\lib\site-packages\jinja2\loaders.py", line 127, in load
    code = environment.compile(source, name, filename)
  File "c:\users\sty_l\microblog\venv\lib\site-packages\jinja2\environment.py", line 638, in compile
    self.handle_exception(source=source_hint)
  File "c:\users\sty_l\microblog\venv\lib\site-packages\jinja2\environment.py", line 832, in handle_exception
    reraise(*rewrite_traceback_stack(source=source))
  File "c:\users\sty_l\microblog\venv\lib\site-packages\jinja2\_compat.py", line 28, in reraise
    raise value.with_traceback(tb)
  File "C:\Users\sty_l\microblog\app\templates\index.html", line 1, in template
    {{% extends "base.html" %}
jinja2.exceptions.TemplateSyntaxError: unexpected '%'
2021-03-02 11:39:05,485 INFO: Microblog startup [in C:\Users\sty_l\microblog\app\__init__.py:44]
2021-03-02 11:39:39,062 INFO: Microblog startup [in C:\Users\sty_l\microblog\app\__init__.py:44]
2021-03-02 11:42:26,586 INFO: Microblog startup [in C:\Users\sty_l\microblog\app\__init__.py:44]
2021-03-02 11:42:37,226 INFO: Microblog startup [in C:\Users\sty_l\microblog\app\__init__.py:44]
2021-03-02 13:26:33,428 INFO: Microblog startup [in C:\Users\sty_l\microblog\app\__init__.py:44]
2021-03-02 13:26:40,300 ERROR: Exception on /explore [GET] [in c:\users\sty_l\microblog\venv\lib\site-packages\flask\app.py:1892]
Traceback (most recent call last):
  File "c:\users\sty_l\microblog\venv\lib\site-packages\flask\app.py", line 2447, in wsgi_app
    response = self.full_dispatch_request()
  File "c:\users\sty_l\microblog\venv\lib\site-packages\flask\app.py", line 1952, in full_dispatch_request
    rv = self.handle_user_exception(e)
  File "c:\users\sty_l\microblog\venv\lib\site-packages\flask\app.py", line 1821, in handle_user_exception
    reraise(exc_type, exc_value, tb)
  File "c:\users\sty_l\microblog\venv\lib\site-packages\flask\_compat.py", line 39, in reraise
    raise value
  File "c:\users\sty_l\microblog\venv\lib\site-packages\flask\app.py", line 1950, in full_dispatch_request
    rv = self.dispatch_request()
  File "c:\users\sty_l\microblog\venv\lib\site-packages\flask\app.py", line 1936, in dispatch_request
    return self.view_functions[rule.endpoint](**req.view_args)
  File "c:\users\sty_l\microblog\venv\lib\site-packages\flask_login\utils.py", line 272, in decorated_view
    return func(*args, **kwargs)
  File "C:\Users\sty_l\microblog\app\routes.py", line 43, in explore
    page, app.config['POSTS_PER_PAGE'], False)
KeyError: 'POSTS_PER_PAGE'
2021-03-02 13:26:51,443 ERROR: Exception on /explore [GET] [in c:\users\sty_l\microblog\venv\lib\site-packages\flask\app.py:1892]
Traceback (most recent call last):
  File "c:\users\sty_l\microblog\venv\lib\site-packages\flask\app.py", line 2447, in wsgi_app
    response = self.full_dispatch_request()
  File "c:\users\sty_l\microblog\venv\lib\site-packages\flask\app.py", line 1952, in full_dispatch_request
    rv = self.handle_user_exception(e)
  File "c:\users\sty_l\microblog\venv\lib\site-packages\flask\app.py", line 1821, in handle_user_exception
    reraise(exc_type, exc_value, tb)
  File "c:\users\sty_l\microblog\venv\lib\site-packages\flask\_compat.py", line 39, in reraise
    raise value
  File "c:\users\sty_l\microblog\venv\lib\site-packages\flask\app.py", line 1950, in full_dispatch_request
    rv = self.dispatch_request()
  File "c:\users\sty_l\microblog\venv\lib\site-packages\flask\app.py", line 1936, in dispatch_request
    return self.view_functions[rule.endpoint](**req.view_args)
  File "c:\users\sty_l\microblog\venv\lib\site-packages\flask_login\utils.py", line 272, in decorated_view
    return func(*args, **kwargs)
  File "C:\Users\sty_l\microblog\app\routes.py", line 43, in explore
    page, app.config['POSTS_PER_PAGE'], False)
KeyError: 'POSTS_PER_PAGE'
2021-03-02 13:28:45,693 INFO: Microblog startup [in C:\Users\sty_l\microblog\app\__init__.py:44]
2021-03-02 13:33:37,859 INFO: Microblog startup [in C:\Users\sty_l\microblog\app\__init__.py:44]
2021-03-02 13:56:18,085 INFO: Microblog startup [in C:\Users\sty_l\microblog\app\__init__.py:46]
2021-03-02 13:58:42,263 INFO: Microblog startup [in C:\Users\sty_l\microblog\app\__init__.py:46]
2021-03-02 14:10:30,473 INFO: Microblog startup [in C:\Users\sty_l\microblog\app\__init__.py:46]
2021-03-02 14:11:11,543 INFO: Microblog startup [in C:\Users\sty_l\microblog\app\__init__.py:46]
2021-03-02 14:22:33,895 INFO: Microblog startup [in C:\Users\sty_l\microblog\app\__init__.py:46]
2021-03-02 14:23:47,323 ERROR: Exception on /reset_password_request [POST] [in c:\users\sty_l\microblog\venv\lib\site-packages\flask\app.py:1892]
Traceback (most recent call last):
  File "c:\users\sty_l\microblog\venv\lib\site-packages\flask\app.py", line 2447, in wsgi_app
    response = self.full_dispatch_request()
  File "c:\users\sty_l\microblog\venv\lib\site-packages\flask\app.py", line 1952, in full_dispatch_request
    rv = self.handle_user_exception(e)
  File "c:\users\sty_l\microblog\venv\lib\site-packages\flask\app.py", line 1821, in handle_user_exception
    reraise(exc_type, exc_value, tb)
  File "c:\users\sty_l\microblog\venv\lib\site-packages\flask\_compat.py", line 39, in reraise
    raise value
  File "c:\users\sty_l\microblog\venv\lib\site-packages\flask\app.py", line 1950, in full_dispatch_request
    rv = self.dispatch_request()
  File "c:\users\sty_l\microblog\venv\lib\site-packages\flask\app.py", line 1936, in dispatch_request
    return self.view_functions[rule.endpoint](**req.view_args)
  File "C:\Users\sty_l\microblog\app\routes.py", line 180, in reset_password_request
    send_password_reset_email(user)
  File "C:\Users\sty_l\microblog\app\email.py", line 14, in send_password_reset_email
    token = user.get_reset_password_token()
  File "C:\Users\sty_l\microblog\app\models.py", line 73, in get_reset_password_token
    app.config['SECRET_KEY'], algorithm='HS256').decode('utf-8')
AttributeError: 'str' object has no attribute 'decode'
2021-03-02 14:26:07,893 INFO: Microblog startup [in C:\Users\sty_l\microblog\app\__init__.py:46]
2021-03-02 14:26:16,754 ERROR: Exception on /reset_password_request [POST] [in c:\users\sty_l\microblog\venv\lib\site-packages\flask\app.py:1892]
Traceback (most recent call last):
  File "c:\users\sty_l\microblog\venv\lib\site-packages\flask\app.py", line 2447, in wsgi_app
    response = self.full_dispatch_request()
  File "c:\users\sty_l\microblog\venv\lib\site-packages\flask\app.py", line 1952, in full_dispatch_request
    rv = self.handle_user_exception(e)
  File "c:\users\sty_l\microblog\venv\lib\site-packages\flask\app.py", line 1821, in handle_user_exception
    reraise(exc_type, exc_value, tb)
  File "c:\users\sty_l\microblog\venv\lib\site-packages\flask\_compat.py", line 39, in reraise
    raise value
  File "c:\users\sty_l\microblog\venv\lib\site-packages\flask\app.py", line 1950, in full_dispatch_request
    rv = self.dispatch_request()
  File "c:\users\sty_l\microblog\venv\lib\site-packages\flask\app.py", line 1936, in dispatch_request
    return self.view_functions[rule.endpoint](**req.view_args)
  File "C:\Users\sty_l\microblog\app\routes.py", line 180, in reset_password_request
    send_password_reset_email(user)
  File "C:\Users\sty_l\microblog\app\email.py", line 14, in send_password_reset_email
    token = user.get_reset_password_token()
  File "C:\Users\sty_l\microblog\app\models.py", line 73, in get_reset_password_token
    app.config['SECRET_KEY'], algorithm='HS256').decode('utf-8')
AttributeError: 'str' object has no attribute 'decode'
2021-03-02 14:28:30,602 INFO: Microblog startup [in C:\Users\sty_l\microblog\app\__init__.py:46]
